<?xml version="1.0"?>
<robot name="warehouse_robot" xmlns:xacro="http://www.ros.org/wiki/xacro">

  <!-- ================= PARAMETERS ================= -->
  <xacro:property name="base_length" value="0.5"/>
  <xacro:property name="base_width" value="0.4"/>
  <xacro:property name="base_height" value="0.2"/>

  <xacro:property name="wheel_radius" value="0.08"/>
  <xacro:property name="wheel_width" value="0.05"/>
  <xacro:property name="wheel_separation" value="0.40"/>

  <!-- ================= ROOT LINK ================= -->
  <link name="world"/>

  <joint name="world_to_base" type="fixed">
    <parent link="world"/>
    <child link="base_link"/>
  </joint>

  <!-- ================= BASE ================= -->
  <link name="base_link">
    <visual>
      <geometry>
        <box size="${base_length} ${base_width} ${base_height}"/>
      </geometry>
      <material name="yellow">
        <color rgba="1.0 0.85 0.0 1.0"/>
      </material>
    </visual>
    <visual>
      <origin xyz="0 0 ${base_height/2 + 0.008}" rpy="0 0 0"/>
      <geometry>
        <box size="${base_length*0.88} ${base_width*0.82} 0.015"/>
      </geometry>
      <material name="top_panel_dark">
        <color rgba="0.18 0.18 0.18 1.0"/>
      </material>
    </visual>
    <visual>
      <origin xyz="${base_length/2 - 0.006} 0 0" rpy="0 0 0"/>
      <geometry>
        <box size="0.012 ${base_width*0.72} ${base_height*0.45}"/>
      </geometry>
      <material name="front_accent_cyan">
        <color rgba="0.0 0.85 1.0 1.0"/>
      </material>
    </visual>

    <collision>
      <geometry>
        <box size="${base_length} ${base_width} ${base_height}"/>
      </geometry>
    </collision>

    <inertial>
      <mass value="8.0"/>
      <inertia ixx="0.2" ixy="0" ixz="0"
               iyy="0.2" iyz="0"
               izz="0.2"/>
    </inertial>
  </link>

  <!-- ================= LEFT WHEEL ================= -->
  <link name="left_wheel">
    <visual>
      <geometry>
        <cylinder radius="${wheel_radius}" length="${wheel_width}"/>
      </geometry>
      <material name="black">
        <color rgba="0 0 0 1"/>
      </material>
    </visual>

    <collision>
      <geometry>
        <cylinder radius="${wheel_radius}" length="${wheel_width}"/>
      </geometry>
    </collision>

    <inertial>
      <mass value="1.0"/>
      <inertia ixx="0.01" ixy="0" ixz="0"
               iyy="0.01" iyz="0"
               izz="0.01"/>
    </inertial>
  </link>

  <joint name="left_wheel_joint" type="continuous">
    <parent link="base_link"/>
    <child link="left_wheel"/>
    <origin xyz="0 ${wheel_separation/2} -${base_height/2}" rpy="1.5707 0 0"/>
    <axis xyz="0 1 0"/>
  </joint>

  <!-- ================= RIGHT WHEEL ================= -->
  <link name="right_wheel">
    <visual>
      <geometry>
        <cylinder radius="${wheel_radius}" length="${wheel_width}"/>
      </geometry>
      <material name="black">
        <color rgba="0 0 0 1"/>
      </material>
    </visual>

    <collision>
      <geometry>
        <cylinder radius="${wheel_radius}" length="${wheel_width}"/>
      </geometry>
    </collision>

    <inertial>
      <mass value="1.0"/>
      <inertia ixx="0.01" ixy="0" ixz="0"
               iyy="0.01" iyz="0"
               izz="0.01"/>
    </inertial>
  </link>

  <joint name="right_wheel_joint" type="continuous">
    <parent link="base_link"/>
    <child link="right_wheel"/>
    <origin xyz="0 -${wheel_separation/2} -${base_height/2}" rpy="1.5707 0 0"/>
    <axis xyz="0 1 0"/>
  </joint>

  <!-- ================= CASTER WHEEL ================= -->
  <link name="caster_wheel">
    <visual>
      <geometry>
        <sphere radius="0.05"/>
      </geometry>
      <material name="gray">
        <color rgba="0.5 0.5 0.5 1"/>
      </material>
    </visual>
  </link>

  <joint name="caster_joint" type="fixed">
    <parent link="base_link"/>
    <child link="caster_wheel"/>
    <origin xyz="-0.2 0 -${base_height/2}"/>
  </joint>

  <!-- ================= LIDAR ================= -->
  <link name="laser_frame">
    <visual>
      <geometry>
        <cylinder radius="0.045" length="0.04"/>
      </geometry>
      <material name="lidar_body">
        <color rgba="0.10 0.10 0.12 1.0"/>
      </material>
    </visual>
    <visual>
      <origin xyz="0 0 0.022" rpy="0 0 0"/>
      <geometry>
        <cylinder radius="0.028" length="0.010"/>
      </geometry>
      <material name="lidar_glow">
        <color rgba="0.0 0.95 1.0 1.0"/>
      </material>
    </visual>
  </link>

  <joint name="laser_joint" type="fixed">
    <parent link="base_link"/>
    <child link="laser_frame"/>
    <origin xyz="0.2 0 ${base_height/2 + 0.025}"/>
  </joint>

  <!-- ================= GAZEBO: DIFF DRIVE ================= -->
  <gazebo>
    <plugin name="gz::sim::systems::DiffDrive" filename="gz-sim-diff-drive-system">
      <left_joint>left_wheel_joint</left_joint>
      <right_joint>right_wheel_joint</right_joint>

      <wheel_separation>${wheel_separation}</wheel_separation>
      <wheel_radius>${wheel_radius}</wheel_radius>

      <odom_publish_frequency>50</odom_publish_frequency>
      <topic>/cmd_vel</topic>
      <odom_topic>/odom</odom_topic>
      <frame_id>odom</frame_id>
      <child_frame_id>base_link</child_frame_id>
    </plugin>
  </gazebo>

  <!-- ================= GAZEBO: LIDAR ================= -->
  <gazebo reference="laser_frame">
    <sensor name="lidar" type="gpu_lidar">
      <update_rate>10</update_rate>
      <topic>/scan</topic>

      <lidar>
        <scan>
          <horizontal>
            <samples>360</samples>
            <resolution>1</resolution>
            <min_angle>-3.1416</min_angle>
            <max_angle>3.1416</max_angle>
          </horizontal>
        </scan>

        <range>
          <min>0.1</min>
          <max>10.0</max>
        </range>
      </lidar>

      <always_on>1</always_on>
      <visualize>false</visualize>
    </sensor>
  </gazebo>

</robot>