<?xml version="1.0"?>
<robot name="warehouse_robot" xmlns:xacro="http://www.ros.org/wiki/xacro">

  <!-- ================= PARAMETERS ================= -->
  <xacro:property name="base_length" value="0.5"/>
  <xacro:property name="base_width" value="0.4"/>
  <xacro:property name="base_height" value="0.2"/>

  <xacro:property name="wheel_radius" value="0.08"/>
  <xacro:property name="wheel_width" value="0.05"/>
  <xacro:property name="wheel_separation" value="0.40"/>

  <!-- ================= BASE (root link) =================
       NOTE: base_link is the ROOT of the kinematic tree.
       Do NOT anchor it to a "world" link with a fixed joint —
       that would pin the robot at the origin and break odom/TF. -->
  <link name="base_link">
    <visual>
      <geometry>
        <box size="${base_length} ${base_width} ${base_height}"/>
      </geometry>
      <material name="yellow">
        <color rgba="1.0 0.85 0.0 1.0"/>
      </material>
    </visual>
    <visual>
      <origin xyz="0 0 ${base_height/2 + 0.008}" rpy="0 0 0"/>
      <geometry>
        <box size="${base_length*0.88} ${base_width*0.82} 0.015"/>
      </geometry>
      <material name="top_panel_dark">
        <color rgba="0.18 0.18 0.18 1.0"/>
      </material>
    </visual>
    <visual>
      <origin xyz="${base_length/2 - 0.006} 0 0" rpy="0 0 0"/>
      <geometry>
        <box size="0.012 ${base_width*0.72} ${base_height*0.45}"/>
      </geometry>
      <material name="front_accent_cyan">
        <color rgba="0.0 0.85 1.0 1.0"/>
      </material>
    </visual>

    <collision>
      <geometry>
        <box size="${base_length} ${base_width} ${base_height}"/>
      </geometry>
    </collision>

    <inertial>
      <mass value="8.0"/>
      <inertia ixx="0.2" ixy="0" ixz="0"
               iyy="0.2" iyz="0"
               izz="0.2"/>
    </inertial>
  </link>

  <!-- ================= WHEEL MACRO =================
       Orientation note: the cylinder is lying on its side via rpy=(π/2, 0, 0),
       so the cylinder's *length* axis (its local Z) now points along the
       parent's Y axis (the axle direction).
       The JOINT AXIS must therefore be (0 0 1) — i.e. the child's Z axis —
       so the wheel rotates about its axle. The previous (0 1 0) made the
       child's Y the rotation axis, which maps to the parent's Z (vertical),
       causing the wheel to spin like a top and scrub sideways.          -->
  <xacro:macro name="drive_wheel" params="side y_sign">
    <link name="${side}_wheel">
      <!-- Tyre -->
      <visual>
        <geometry>
          <cylinder radius="${wheel_radius}" length="${wheel_width}"/>
        </geometry>
        <material name="tyre_black">
          <color rgba="0.05 0.05 0.05 1"/>
        </material>
      </visual>
      <!-- Hub (bright disk) so we can see the wheel rotate -->
      <visual>
        <origin xyz="0 0 ${wheel_width/2 + 0.001}" rpy="0 0 0"/>
        <geometry>
          <cylinder radius="${wheel_radius*0.45}" length="0.004"/>
        </geometry>
        <material name="wheel_hub">
          <color rgba="0.85 0.85 0.90 1"/>
        </material>
      </visual>
      <!-- Spoke 1: asymmetric stripe from hub to rim. Because the cylinder's
           local Z is the axle direction, a box offset along local X rotates
           visibly around the axle as the joint spins. -->
      <visual>
        <origin xyz="${wheel_radius*0.6} 0 ${wheel_width/2 + 0.002}" rpy="0 0 0"/>
        <geometry>
          <box size="${wheel_radius*0.7} 0.012 0.006"/>
        </geometry>
        <material name="spoke_cyan">
          <color rgba="0.0 0.85 1.0 1.0"/>
        </material>
      </visual>
      <!-- Spoke 2: perpendicular, different colour -->
      <visual>
        <origin xyz="0 ${wheel_radius*0.6} ${wheel_width/2 + 0.002}" rpy="0 0 0"/>
        <geometry>
          <box size="0.012 ${wheel_radius*0.7} 0.006"/>
        </geometry>
        <material name="spoke_yellow">
          <color rgba="1.0 0.85 0.0 1.0"/>
        </material>
      </visual>

      <collision>
        <geometry>
          <cylinder radius="${wheel_radius}" length="${wheel_width}"/>
        </geometry>
      </collision>

      <inertial>
        <mass value="1.0"/>
        <inertia ixx="0.01" ixy="0" ixz="0"
                 iyy="0.01" iyz="0"
                 izz="0.01"/>
      </inertial>
    </link>

    <joint name="${side}_wheel_joint" type="continuous">
      <parent link="base_link"/>
      <child link="${side}_wheel"/>
      <origin xyz="0 ${y_sign*wheel_separation/2} -${base_height/2}" rpy="1.5707 0 0"/>
      <!-- Axle axis (child Z == parent Y after the rpy rotation above) -->
      <axis xyz="0 0 1"/>
      <dynamics damping="0.01" friction="0.0"/>
    </joint>

    <!-- Good rolling friction for wheels -->
    <gazebo reference="${side}_wheel">
      <mu1>1.0</mu1>
      <mu2>1.0</mu2>
      <kp>1000000.0</kp>
      <kd>100.0</kd>
    </gazebo>
  </xacro:macro>

  <xacro:drive_wheel side="left"  y_sign="1"/>
  <xacro:drive_wheel side="right" y_sign="-1"/>

  <!-- ================= CASTER WHEEL ================= -->
  <link name="caster_wheel">
    <visual>
      <geometry>
        <sphere radius="0.05"/>
      </geometry>
      <material name="gray">
        <color rgba="0.5 0.5 0.5 1"/>
      </material>
    </visual>

    <collision>
      <geometry>
        <sphere radius="0.05"/>
      </geometry>
      <surface>
        <friction>
          <ode>
            <mu>0.0</mu>
            <mu2>0.0</mu2>
          </ode>
        </friction>
      </surface>
    </collision>

    <inertial>
      <mass value="0.2"/>
      <inertia ixx="0.0005" ixy="0" ixz="0"
               iyy="0.0005" iyz="0"
               izz="0.0005"/>
    </inertial>
  </link>

  <joint name="caster_joint" type="fixed">
    <parent link="base_link"/>
    <child link="caster_wheel"/>
    <origin xyz="-0.2 0 -${base_height/2}"/>
  </joint>

  <!-- Low-friction caster surface for Gazebo -->
  <gazebo reference="caster_wheel">
    <mu1>0.0</mu1>
    <mu2>0.0</mu2>
  </gazebo>

  <!-- ================= LIDAR ================= -->
  <link name="laser_frame">
    <visual>
      <geometry>
        <cylinder radius="0.045" length="0.04"/>
      </geometry>
      <material name="lidar_body">
        <color rgba="0.10 0.10 0.12 1.0"/>
      </material>
    </visual>
    <visual>
      <origin xyz="0 0 0.022" rpy="0 0 0"/>
      <geometry>
        <cylinder radius="0.028" length="0.010"/>
      </geometry>
      <material name="lidar_glow">
        <color rgba="0.0 0.95 1.0 1.0"/>
      </material>
    </visual>

    <collision>
      <geometry>
        <cylinder radius="0.045" length="0.04"/>
      </geometry>
    </collision>

    <inertial>
      <mass value="0.1"/>
      <inertia ixx="0.0001" ixy="0" ixz="0"
               iyy="0.0001" iyz="0"
               izz="0.0001"/>
    </inertial>
  </link>

  <joint name="laser_joint" type="fixed">
    <parent link="base_link"/>
    <child link="laser_frame"/>
    <origin xyz="0.2 0 ${base_height/2 + 0.025}"/>
  </joint>

  <!-- ================= GAZEBO: DIFF DRIVE =================
       Publishes:
         - Reads  geometry_msgs/Twist on gz topic  /cmd_vel
         - Writes nav_msgs/Odometry   on gz topic  /odom
         - Writes TF (Pose_V)         on gz topic  /tf
         These are bridged to ROS in the launch file. -->
  <gazebo>
    <plugin filename="gz-sim-diff-drive-system"
            name="gz::sim::systems::DiffDrive">
      <left_joint>left_wheel_joint</left_joint>
      <right_joint>right_wheel_joint</right_joint>

      <wheel_separation>${wheel_separation}</wheel_separation>
      <wheel_radius>${wheel_radius}</wheel_radius>

      <odom_publish_frequency>50</odom_publish_frequency>
      <topic>/cmd_vel</topic>
      <odom_topic>/odom</odom_topic>
      <tf_topic>/tf</tf_topic>
      <frame_id>odom</frame_id>
      <child_frame_id>base_link</child_frame_id>
      <!-- Sane accel/velocity limits so the bot doesn't rocket off -->
      <max_linear_acceleration>2.0</max_linear_acceleration>
      <max_angular_acceleration>4.0</max_angular_acceleration>
    </plugin>

    <!-- Publishes simulation time on gz topic /clock -->
    <plugin filename="gz-sim-joint-state-publisher-system"
            name="gz::sim::systems::JointStatePublisher">
      <topic>/joint_states</topic>
      <joint_name>left_wheel_joint</joint_name>
      <joint_name>right_wheel_joint</joint_name>
    </plugin>
  </gazebo>

  <!-- ================= GAZEBO: LIDAR ================= -->
  <gazebo reference="laser_frame">
    <sensor name="lidar" type="gpu_lidar">
      <update_rate>10</update_rate>
      <topic>/scan</topic>
      <gz_frame_id>laser_frame</gz_frame_id>

      <lidar>
        <scan>
          <horizontal>
            <samples>360</samples>
            <resolution>1</resolution>
            <min_angle>-3.1416</min_angle>
            <max_angle>3.1416</max_angle>
          </horizontal>
        </scan>

        <range>
          <min>0.1</min>
          <max>10.0</max>
        </range>
      </lidar>

      <always_on>1</always_on>
      <visualize>false</visualize>
    </sensor>
  </gazebo>

</robot>
